<?xml version="1.0" ?>
<sdf version="1.9">
  <model name="custom_self_balancing_robot">
    <plugin filename="gz-sim-diff-drive-system" name="gz::sim::systems::DiffDrive">
        <left_joint>left_rod_to_left_wheel</left_joint>
        <right_joint>right_rod_to_right_wheel</right_joint>
        <wheel_separation>0.62</wheel_separation> 
        <wheel_radius>0.18</wheel_radius>         
        <odom_publish_frequency>50</odom_publish_frequency>
        <topic>/cmd_vel</topic>
        <odom_topic>/odom</odom_topic>
        <tf_topic>/tf</tf_topic>
        <frame_id>odom</frame_id>
        <child_frame_id>chassis</child_frame_id>
    </plugin>
    <plugin
      filename="gz-sim-sensors-system"
      name="gz::sim::systems::Sensors">
      <render_engine>ogre2</render_engine>
    </plugin>
    <plugin filename="gz-sim-imu-system"
        name="gz::sim::systems::Imu">
    </plugin>

    <static>false</static>

    
    <link name="chassis">       
      <sensor name="imu_sensor" type="imu">
        <always_on>1</always_on>
        <update_rate>1000</update_rate> 
        <visualize>true</visualize>
        <topic>/imu</topic>
      </sensor>

      <pose>0 0 0.11 0 0 0</pose>
      <visual name="chassis_visual">
        <geometry>
          <box>
            <size>0.4 0.3 0.1</size>
          </box>
        </geometry>
        <material>
          <ambient>1 0 0 1</ambient>
          <diffuse>1 0 0 1</diffuse>
        </material>
      </visual>
      <collision name="chassis_collision">
        <geometry>
          <box>
            <size>0.4 0.3 0.1</size>
          </box>
        </geometry>
      </collision>
      <inertial>
        <mass>2.0</mass>
        <inertia>
          <ixx>0.05</ixx>
          <iyy>0.05</iyy>
          <izz>0.05</izz>
        </inertia>
      </inertial>
    </link>

    
    <link name="left_rod">
      <pose>0 0.253 0.13 1.5708 0 0</pose> 
      <visual name="left_rod_visual">
        <geometry>
          <cylinder>
            <radius>0.02</radius>
            <length>0.19</length> 
          </cylinder>
        </geometry>
        <material>
          <ambient>0 1 0 1</ambient>
          <diffuse>0 1 0 1</diffuse>
        </material>
      </visual>
      <collision name="left_rod_collision">
        <geometry>
          <cylinder>
            <radius>0.02</radius>
            <length>0.19</length>
          </cylinder>
        </geometry>
      </collision>
      <inertial>
        <mass>0.1</mass>
        <inertia>
          <ixx>0.001</ixx>
          <iyy>0.001</iyy>
          <izz>0.001</izz>
        </inertia>
      </inertial>
    </link>

    
    <link name="right_rod">
      <pose>0 -0.253 0.13 1.5708 0 0</pose> 
      <visual name="right_rod_visual">
        <geometry>
          <cylinder>
            <radius>0.02</radius>
            <length>0.19</length>
          </cylinder>
        </geometry>
        <material>
          <ambient>0 1 0 1</ambient>
          <diffuse>0 1 0 1</diffuse>
        </material>
      </visual>
      <collision name="right_rod_collision">
        <geometry>
          <cylinder>
            <radius>0.02</radius>
            <length>0.19</length>
          </cylinder>
        </geometry>
      </collision>
      <inertial>
        <mass>0.1</mass>
        <inertia>
          <ixx>0.001</ixx>
          <iyy>0.001</iyy>
          <izz>0.001</izz>
        </inertia>
      </inertial>
    </link>

    
    <link name="left_wheel">
      <pose>0 0.31 0.08 -1.5708 0 0</pose> 
      <visual name="left_wheel_visual">
        <geometry>
          <cylinder>
            <radius>0.18</radius>
            <length>0.1</length>
          </cylinder>
        </geometry>
        <material>
          <ambient>0 0 1 1</ambient>
          <diffuse>0 0 1 1</diffuse>
        </material>
      </visual>
      <collision name="left_wheel_collision">
        <geometry>
          <cylinder>
            <radius>0.18</radius>
            <length>0.1</length>
          </cylinder>
        </geometry>
      </collision>
      <inertial>
        <mass>0.3</mass>
        <inertia>
          <ixx>0.004</ixx>
          <iyy>0.004</iyy>
          <izz>0.004</izz>
        </inertia>
      </inertial>
    </link>

    <link name="support_rod">
      <pose>-0.20 0 0.05 0 0 0</pose>
      <inertial>
        <mass>0.001</mass>
        <inertia>
          <ixx>1e-6</ixx><iyy>1e-6</iyy><izz>1e-6</izz>
          <ixy>0</ixy><ixz>0</ixz><iyz>0</iyz>
        </inertia>
      </inertial>
      <collision name="collision">
        <geometry>
          <cylinder>
            <radius>0.01</radius>
            <length>0.16</length>
          </cylinder>
        </geometry>
      </collision>
      <visual name="visual">
        <geometry>
          <cylinder>
            <radius>0.01</radius>
            <length>0.16</length>
          </cylinder>
        </geometry>
        <material>
          <ambient>1 1 1 1</ambient>
          <diffuse>1 1 1 1</diffuse>
        </material>
        <transparency>1.0</transparency>
      </visual>
    </link>
    
    <link name="right_wheel">
      <pose>0 -0.31 0.08 -1.5708 0 0</pose>
      <visual name="right_wheel_visual">
        <geometry>
          <cylinder>
            <radius>0.18</radius>
            <length>0.1</length>
          </cylinder>
        </geometry>
        <material>
          <ambient>0 0 1 1</ambient>
          <diffuse>0 0 1 1</diffuse>
        </material>
      </visual>
      <collision name="right_wheel_collision">
        <geometry>
          <cylinder>
            <radius>0.18</radius>
            <length>0.1</length>
          </cylinder>
        </geometry>
      </collision>
      <inertial>
        <mass>0.3</mass>
        <inertia>
          <ixx>0.004</ixx>
          <iyy>0.004</iyy>
          <izz>0.004</izz>
        </inertia>
      </inertial>
    </link>
    <link name="support_rod_front">
      <pose>0.18 0 0.05 0 0 0</pose>
      <visual name="support_rod_front_visual">
        <geometry>
          <cylinder>
            <radius>0.01</radius>
            <length>0.16</length>
          </cylinder>
        </geometry>
        <material>
          <ambient>0 0 0 0</ambient>
          <diffuse>0 0 0 0</diffuse>
        </material>
        <transparency>1.0</transparency>
      </visual>
      <collision name="support_rod_front_collision">
        <geometry>
          <cylinder>
            <radius>0.01</radius>
            <length>0.16</length>
          </cylinder>
        </geometry>
      </collision>
      <inertial>
        <mass>0.001</mass>
        <inertia>
          <ixx>0.000001</ixx>
          <iyy>0.000001</iyy>
          <izz>0.000001</izz>
        </inertia>
      </inertial>
    </link>
    
    <link name="support_wheel">
      <pose>-0.20 0 -0.05 1.5708 0 0</pose> <!-- Slightly below the support rod -->
      <visual name="support_wheel_visual">
        <geometry>
          <cylinder>
            <radius>0.04</radius> <!-- Smaller than main wheels -->
            <length>0.02</length>
          </cylinder>
        </geometry>
        <material>
          <ambient>0 0 0 0</ambient>
          <diffuse>0 0 0 0</diffuse>
        </material>
        <transparency>1.0</transparency>
      </visual>
      <collision name="support_wheel_collision">
        <geometry>
          <cylinder>
            <radius>0.04</radius>
            <length>0.02</length>
          </cylinder>
        </geometry>
      </collision>
      <inertial>
        <mass>0.05</mass>
        <inertia>
          <ixx>0.0001</ixx>
          <iyy>0.0001</iyy>
          <izz>0.0001</izz>
        </inertia>
      </inertial>
    </link>
    <link name="support_wheel_front">
      <pose>0 0 -0.05 1.5708 0 0</pose>
      <visual name="support_wheel_front_visual">
        <geometry>
          <cylinder>
            <radius>0.04</radius>
            <length>0.02</length>
          </cylinder>
        </geometry>
        <material>
          <ambient>0 0 0 0</ambient>
          <diffuse>0 0 0 0</diffuse>
        </material>
        <transparency>1.0</transparency>
      </visual>
      <collision name="support_wheel_front_collision">
        <geometry>
          <cylinder>
            <radius>0.04</radius>
            <length>0.02</length>
          </cylinder>
        </geometry>
      </collision>
      <inertial>
        <mass>0.05</mass>
        <inertia>
          <ixx>0.0001</ixx>
          <iyy>0.0001</iyy>
          <izz>0.0001</izz>
        </inertia>
      </inertial>
    </link>

    <link name="lidar_link">
      <pose>0 0 0.13 0 0 0</pose>
      <sensor name="gpu_lidar" type="gpu_lidar">
        <pose>0 0 0 0 0 0</pose>
        <topic>/scan</topic>
        <update_rate>10</update_rate>
        <ray>
          <scan>
            <horizontal>
              <samples>640</samples>
              <resolution>1</resolution>
              <min_angle>-1.396263</min_angle>
              <max_angle>1.396263</max_angle>
            </horizontal>
            <vertical>
              <samples>1</samples>
              <resolution>0.01</resolution>
              <min_angle>0</min_angle>
              <max_angle>0</max_angle>
            </vertical>
          </scan>
          <range>
            <min>0.08</min>
            <max>150.0</max>
            <resolution>0.01</resolution>
          </range>
        </ray>
        <always_on>1</always_on>
        <visualize>true</visualize>
      </sensor>
    </link>

    <joint name="lidar_joint" type="fixed">
      <parent>chassis</parent>
      <child>lidar_link</child>
      <pose>0 0 0 0 0 0</pose>
    </joint>
       
    <joint name="chassis_to_left_rod" type="fixed">
      <parent>chassis</parent>
      <child>left_rod</child>
      <pose>0 0 0 0 0 0</pose>
    </joint>

    <joint name="chassis_to_right_rod" type="fixed">
      <parent>chassis</parent>
      <child>right_rod</child>
      <pose>0 0 0 0 0 0</pose>
    </joint>

    <joint name="left_rod_to_left_wheel" type="revolute">
      <parent>left_rod</parent>
      <child>left_wheel</child>
      <pose>0 0 0 0 0 0</pose>
      <axis>
        <xyz>0 0 1</xyz>
        <limit>
          <lower>-1000</lower>
          <upper>1000</upper>
          <effort>15</effort>
          <velocity>30</velocity>
        </limit>
        <dynamics>
          <damping>0.1</damping>
          <friction>0.1</friction>
        </dynamics>
      </axis>
    </joint>

    <joint name="right_rod_to_right_wheel" type="revolute">
      <parent>right_rod</parent>
      <child>right_wheel</child>
      <pose>0 0 0 0 0 0</pose>
      <axis>
        <xyz>0 0 1</xyz>
        <limit>
          <lower>-1000</lower>
          <upper>1000</upper>
          <effort>15</effort>
          <velocity>30</velocity>
        </limit>
        <dynamics>
          <damping>0.1</damping>
          <friction>0.1</friction>
        </dynamics>
      </axis>
    </joint>
    <joint name="support_joint" type="fixed">
      <parent>chassis</parent>
      <child>support_rod</child>
      <pose>-0.20 0 0.05 0 0 0</pose>
    </joint>
    <joint name="support_joint_front" type="fixed">
      <parent>chassis</parent>
      <child>support_rod_front</child>
      <pose>0.18 0 0.05 0 0 0</pose>
    </joint>
    <joint name="support_to_support_wheel" type="revolute">
      
      <parent>support_rod</parent>
      <child>support_wheel</child>
      <axis>
        <xyz>0 0 1</xyz>
      </axis>
    </joint>
    <joint name="support_to_support_wheel_front" type="revolute">
      
      <parent>support_rod_front</parent>
      <child>support_wheel_front</child>
      <axis>
        <xyz>0 0 1</xyz>
      </axis>
    </joint>

  </model>
</sdf>
